<?xml version="1.0"?>

<robot name="drone">

  <!-- Base Link -->
  <link name="base_link">
    <visual>
      <geometry>
        <cylinder length="0.1" radius="0.05"/>
      </geometry>
      <origin rpy="0 0 0" xyz="0 0 0.05"/>
      <material name="blue">
        <color rgba="0 0 1 1"/>
      </material>
    </visual>
    <inertial>
      <mass value="1"/>
      <inertia ixx="0.01" ixy="0" ixz="0" iyy="0.01" iyz="0" izz="0.01"/>
    </inertial>
  </link>

  <!-- Propellers -->
  <joint name="joint_propeller1" type="continuous">
    <parent link="base_link"/>
    <child link="propeller1"/>
    <origin rpy="0 0 0" xyz="0.05 0 0"/>
    <axis xyz="0 0 1"/>
  </joint>
  <link name="propeller1">
    <visual>
      <geometry>
        <cylinder length="0.02" radius="0.05"/>
      </geometry>
      <origin rpy="0 0 0" xyz="0.02 0 0"/>
      <material name="red">
        <color rgba="1 0 0 1"/>
      </material>
    </visual>
    <inertial>
      <mass value="0.01"/>
      <inertia ixx="1e-6" ixy="0" ixz="0" iyy="1e-6" iyz="0" izz="1e-6"/>
    </inertial>
  </link>

  <!-- Repeat for other propellers -->

</robot>
